Workbook

Sheet Raw Data
A1: Source Month | B1: Source File | C1: Sl. No. | D1: Regions | E1: State | F1: Sector Category | G1: Category | H1: Stations | I1: Monitored Capacity (MW) - Col (1) | J1: Target April 2023 to Mach 2024 - Col (2) | K1: July` 2023 - Program - Col (3) | L1: July` 2023 - Actual - Col (4) | M1: July` 2023 - Actual Same Month 2022-23 - Col (5) | N1: July` 2023 - % of Program Col. (4/3) - Col (6) | O1: July` 2023 - % of Last Year Col. (4/5) - Col (7) | P1: April` 2023 to July` 2023 - Program - Col (8) | Q1: April` 2023 to July` 2023 - Actual - Col (9) | R1: April` 2023 to July` 2023 - Actual Same Period 2022-23 - Col (10) | S1: April` 2023 to July` 2023 - % of Program Col. (9/8) - Col (11) | T1: April` 2023 to July` 2023 - % of Last Year Col. (9/10) - Col (12) | U1: Plant Load Factor (%) - July` 2023 - Program - Col (13) | V1: Plant Load Factor (%) - July` 2023 - Actual - Col (14) | W1: Plant Load Factor (%) - July` 2023 - Actual Same Month 2022-23 - Col (15) | X1: Plant Load Factor (%) - April` 2023 to July` 2023 - Program - Col (16) | Y1: Plant Load Factor (%) - April` 2023 to July` 2023 - Actual - Col (17) | Z1: Plant Load Factor (%) - April` 2023 to July` 2023 - Actual Same Peroid 2022-23 - Col (18)
A2: July 2023 | B2: power_generation_2023_07_july.csv | C2: 1 | D2: Northern Region | E2: Delhi | F2: State Sector | G2: I.P.CCPP | H2: NA | I2: 270 | J2: 175 | K2: 12 | L2: 27.58 | M2: 27.58 | N2: 229.83 | O2: 100 | P2: 65 | Q2: 108.45 | R2: 115.04 | S2: 166.85 | T2: 94.27 | U2: NA | V2: NA | W2: NA | X2: NA | Y2: NA | Z2: NA
A3: July 2023 | B3: power_generation_2023_07_july.csv | C3: 2 | D3: Northern Region | E3: Delhi | F3: State Sector | G3: IPGCL | H3: Natural Gas | I3: 270 | J3: 175 | K3: 12 | L3: 27.58 | M3: 27.58 | N3: 229.83 | O3: 100 | P3: 65 | Q3: 108.45 | R3: 115.04 | S3: 166.85 | T3: 94.27 | U3: NA | V3: NA | W3: NA | X3: NA | Y3: NA | Z3: NA
A4: July 2023 | B4: power_generation_2023_07_july.csv | C4: 3 | D4: Northern Region | E4: Delhi | F4: State Sector | G4: PRAGATI CCGT-III | H4: NA | I4: 1500 | J4: 4100 | K4: 342 | L4: 91.46 | M4: 214.86 | N4: 26.74 | O4: 42.57 | P4: 1408 | Q4: 468.99 | R4: 1110.39 | S4: 33.31 | T4: 42.24 | U4: NA | V4: NA | W4: NA | X4: NA | Y4: NA | Z4: NA
A5: July 2023 | B5: power_generation_2023_07_july.csv | C5: 4 | D5: Northern Region | E5: Delhi | F5: State Sector | G5: PRAGATI CCPP | H5: NA | I5: 330.4 | J5: 1500 | K5: 119 | L5: 121.82 | M5: 132.37 | N5: 102.37 | O5: 92.03 | P5: 576 | Q5: 337.64 | R5: 565.24 | S5: 58.62 | T5: 59.73 | U5: NA | V5: NA | W5: NA | X5: NA | Y5: NA | Z5: NA
A6: July 2023 | B6: power_generation_2023_07_july.csv | C6: 5 | D6: Northern Region | E6: Delhi | F6: State Sector | G6: PPCL | H6: Natural Gas | I6: 1830.4 | J6: 5600 | K6: 461 | L6: 213.28 | M6: 347.23 | N6: 46.26 | O6: 61.42 | P6: 1984 | Q6: 806.63 | R6: 1675.63 | S6: 40.66 | T6: 48.14 | U6: NA | V6: NA | W6: NA | X6: NA | Y6: NA | Z6: NA
A7: July 2023 | B7: power_generation_2023_07_july.csv | C7: 6 | D7: Northern Region | E7: Delhi | F7: State Sector | G7: State Sector | H7: Natural Gas | I7: 2100.4 | J7: 5775 | K7: 473 | L7: 240.86 | M7: 374.81 | N7: 50.92 | O7: 64.26 | P7: 2049 | Q7: 915.08 | R7: 1790.67 | S7: 44.66 | T7: 51.1 | U7: NA | V7: NA | W7: NA | X7: NA | Y7: NA | Z7: NA
A8: July 2023 | B8: power_generation_2023_07_july.csv | C8: 7 | D8: Northern Region | E8: Delhi | F8: Pvt Sector | G8: RITHALA CCPP | H8: NA | I8: 108 | J8: 0 | K8: 0 | L8: 0 | M8: 0 | N8: 0 | O8: 0 | P8: 0 | Q8: 0 | R8: 0 | S8: 0 | T8: 0 | U8: NA | V8: NA | W8: NA | X8: NA | Y8: NA | Z8: NA
A9: July 2023 | B9: power_generation_2023_07_july.csv | C9: 8 | D9: Northern Region | E9: Delhi | F9: Pvt Sector | G9: TPDDL | H9: Natural Gas | I9: 108 | J9: 0 | K9: 0 | L9: 0 | M9: 0 | N9: 0 | O9: 0 | P9: 0 | Q9: 0 | R9: 0 | S9: 0 | T9: 0 | U9: NA | V9: NA | W9: NA | X9: NA | Y9: NA | Z9: NA
A10: July 2023 | B10: power_generation_2023_07_july.csv | C10: 9 | D10: Northern Region | E10: Delhi | F10: Pvt Sector | G10: Pvt Sector | H10: Natural Gas | I10: 108 | J10: 0 | K10: 0 | L10: 0 | M10: 0 | N10: 0 | O10: 0 | P10: 0 | Q10: 0 | R10: 0 | S10: 0 | T10: 0 | U10: NA | V10: NA | W10: NA | X10: NA | Y10: NA | Z10: NA
A11: July 2023 | B11: power_generation_2023_07_july.csv | C11: 10 | D11: Northern Region | E11: Delhi | F11: Pvt Sector | G11: Total | H11: Natural Gas | I11: 2208.4 | J11: 5775 | K11: 473 | L11: 240.86 | M11: 374.81 | N11: 50.92 | O11: 64.26 | P11: 2049 | Q11: 915.08 | R11: 1790.67 | S11: 44.66 | T11: 51.1 | U11: NA | V11: NA | W11: NA | X11: NA | Y11: NA | Z11: NA
A12: July 2023 | B12: power_generation_2023_07_july.csv | C12: 11 | D12: Northern Region | E12: Delhi | F12: Pvt Sector | G12: Total | H12: Delhi | I12: 2208.4 | J12: 5775 | K12: 473 | L12: 240.86 | M12: 374.81 | N12: 50.92 | O12: 64.26 | P12: 2049 | Q12: 915.08 | R12: 1790.67 | S12: 44.66 | T12: 51.1 | U12: NA | V12: NA | W12: NA | X12: NA | Y12: NA | Z12: NA
A13: July 2023 | B13: power_generation_2023_07_july.csv | C13: 12 | D13: Northern Region | E13: Haryana | F13: State Sector | G13: PANIPAT TPS | H13: NA | I13: 710 | J13: 4000 | K13: 305 | L13: 430.22 | M13: 458.14 | N13: 141.06 | O13: 93.91 | P13: 1446 | Q13: 1306.99 | R13: 1789.02 | S13: 90.39 | T13: 73.06 | U13: 57.74 | V13: 81.44 | W13: 86.73 | X13: 69.56 | Y13: 62.87 | Z13: 86.06
A14: July 2023 | B14: power_generation_2023_07_july.csv | C14: 13 | D14: Northern Region | E14: Haryana | F14: State Sector | G14: RAJIV GANDHI TPS | H14: NA | I14: 1200 | J14: 6100 | K14: 553 | L14: 267.13 | M14: 620.32 | N14: 48.31 | O14: 43.06 | P14: 2591 | Q14: 1433.98 | R14: 1945.6 | S14: 55.34 | T14: 73.7 | U14: 61.94 | V14: 29.92 | W14: 69.48 | X14: 73.74 | Y14: 40.81 | Z14: 55.37
A15: July 2023 | B15: power_generation_2023_07_july.csv | C15: 14 | D15: Northern Region | E15: Haryana | F15: State Sector | G15: YAMUNA NAGAR TPS | H15: NA | I15: 600 | J15: 4200 | K15: 320 | L15: 293.92 | M15: 370.68 | N15: 91.85 | O15: 79.29 | P15: 1438 | Q15: 1209.31 | R15: 1523.84 | S15: 84.1 | T15: 79.36 | U15: 71.68 | V15: 65.84 | W15: 83.04 | X15: 81.85 | Y15: 68.84 | Z15: 86.74
A16: July 2023 | B16: power_generation_2023_07_july.csv | C16: 15 | D16: Northern Region | E16: Haryana | F16: State Sector | G16: HPGCL | H16: Coal | I16: 2510 | J16: 14300 | K16: 1178 | L16: 991.27 | M16: 1449.14 | N16: 84.15 | O16: 68.4 | P16: 5475 | Q16: 3950.28 | R16: 5258.46 | S16: 72.15 | T16: 75.12 | U16: 63.08 | V16: 53.08 | W16: 77.6 | X16: 74.5 | Y16: 53.75 | Z16: 71.55
A17: July 2023 | B17: power_generation_2023_07_july.csv | C17: 16 | D17: Northern Region | E17: Haryana | F17: State Sector | G17: State Sector | H17: Thermal | I17: 2510 | J17: 14300 | K17: 1178 | L17: 991.27 | M17: 1449.14 | N17: 84.15 | O17: 68.4 | P17: 5475 | Q17: 3950.28 | R17: 5258.46 | S17: 72.15 | T17: 75.12 | U17: 63.08 | V17: 53.08 | W17: 77.6 | X17: 74.5 | Y17: 53.75 | Z17: 71.55
A18: July 2023 | B18: power_generation_2023_07_july.csv | C18: 17 | D18: Northern Region | E18: Haryana | F18: Pvt Sector | G18: MAHATMA GANDHI TPS | H18: NA | I18: 1320 | J18: 7600 | K18: 614 | L18: 718.48 | M18: 801.6 | N18: 117.02 | O18: 89.63 | P18: 2868 | Q18: 2718.87 | R18: 3007.71 | S18: 94.8 | T18: 90.4 | U18: 62.52 | V18: 73.16 | W18: 81.62 | X18: 74.21 | Y18: 70.35 | Z18: 77.82
A19: July 2023 | B19: power_generation_2023_07_july.csv | C19: 18 | D19: Northern Region | E19: Haryana | F19: Pvt Sector | G19: JhPL (HR) | H19: Coal | I19: 1320 | J19: 7600 | K19: 614 | L19: 718.48 | M19: 801.6 | N19: 117.02 | O19: 89.63 | P19: 2868 | Q19: 2718.87 | R19: 3007.71 | S19: 94.8 | T19: 90.4 | U19: 62.52 | V19: 73.16 | W19: 81.62 | X19: 74.21 | Y19: 70.35 | Z19: 77.82
A20: July 2023 | B20: power_generation_2023_07_july.csv | C20: 19 | D20: Northern Region | E20: Haryana | F20: Pvt Sector | G20: Pvt Sector | H20: Thermal | I20: 1320 | J20: 7600 | K20: 614 | L20: 718.48 | M20: 801.6 | N20: 117.02 | O20: 89.63 | P20: 2868 | Q20: 2718.87 | R20: 3007.71 | S20: 94.8 | T20: 90.4 | U20: 62.52 | V20: 73.16 | W20: 81.62 | X20: 74.21 | Y20: 70.35 | Z20: 77.82
A21: July 2023 | B21: power_generation_2023_07_july.csv | C21: 20 | D21: Northern Region | E21: Haryana | F21: Central Sector | G21: INDIRA GANDHI STPP | H21: NA | I21: 1500 | J21: 7600 | K21: 603 | L21: 675.5 | M21: 710.2 | N21: 112.02 | O21: 95.11 | P21: 2865 | Q21: 2585.29 | R21: 3502.71 | S21: 90.24 | T21: 73.81 | U21: 54.03 | V21: 60.53 | W21: 63.64 | X21: 65.23 | Y21: 58.86 | Z21: 79.75
A22: July 2023 | B22: power_generation_2023_07_july.csv | C22: 21 | D22: Northern Region | E22: Haryana | F22: Central Sector | G22: APCPL | H22: Coal | I22: 1500 | J22: 7600 | K22: 603 | L22: 675.5 | M22: 710.2 | N22: 112.02 | O22: 95.11 | P22: 2865 | Q22: 2585.29 | R22: 3502.71 | S22: 90.24 | T22: 73.81 | U22: 54.03 | V22: 60.53 | W22: 63.64 | X22: 65.23 | Y22: 58.86 | Z22: 79.75
A23: July 2023 | B23: power_generation_2023_07_july.csv | C23: 22 | D23: Northern Region | E23: Haryana | F23: Central Sector | G23: CENTRAL | H23: Thermal | I23: 1500 | J23: 7600 | K23: 603 | L23: 675.5 | M23: 710.2 | N23: 112.02 | O23: 95.11 | P23: 2865 | Q23: 2585.29 | R23: 3502.71 | S23: 90.24 | T23: 73.81 | U23: 54.03 | V23: 60.53 | W23: 63.64 | X23: 65.23 | Y23: 58.86 | Z23: 79.75
A24: July 2023 | B24: power_generation_2023_07_july.csv | C24: 23 | D24: Northern Region | E24: Haryana | F24: Central Sector | G24: FARIDABAD CCPP | H24: NA | I24: 431.59 | J24: 150 | K24: 12 | L24: 0.01 | M24: 0 | N24: 0.08 | O24: 0 | P24: 51 | Q24: 70.2 | R24: 2.55 | S24: 137.65 | T24: 2752.94 | U24: NA | V24: NA | W24: NA | X24: NA | Y24: NA | Z24: NA
A25: July 2023 | B25: power_generation_2023_07_july.csv | C25: 24 | D25: Northern Region | E25: Haryana | F25: Central Sector | G25: NTPC Ltd. | H25: Natural Gas | I25: 431.59 | J25: 150 | K25: 12 | L25: 0.01 | M25: 0 | N25: 0.08 | O25: 0 | P25: 51 | Q25: 70.2 | R25: 2.55 | S25: 137.65 | T25: 2752.94 | U25: NA | V25: NA | W25: NA | X25: NA | Y25: NA | Z25: NA
A26: July 2023 | B26: power_generation_2023_07_july.csv | C26: 25 | D26: Northern Region | E26: Haryana | F26: Central Sector | G26: Central | H26: Natural Gas | I26: 431.59 | J26: 150 | K26: 12 | L26: 0.01 | M26: 0 | N26: 0.08 | O26: 0 | P26: 51 | Q26: 70.2 | R26: 2.55 | S26: 137.65 | T26: 2752.94 | U26: NA | V26: NA | W26: NA | X26: NA | Y26: NA | Z26: NA
A27: July 2023 | B27: power_generation_2023_07_july.csv | C27: 26 | D27: Northern Region | E27: Haryana | F27: Central Sector | G27: Total | H27: Thermal | I27: 5330 | J27: 29500 | K27: 2395 | L27: 2385.25 | M27: 2960.94 | N27: 99.59 | O27: 80.56 | P27: 11208 | Q27: 9254.44 | R27: 11768.88 | S27: 82.57 | T27: 78.63 | U27: 60.4 | V27: 60.15 | W27: 74.67 | X27: 71.82 | Y27: 59.3 | Z27: 75.41
A28: July 2023 | B28: power_generation_2023_07_july.csv | C28: 27 | D28: Northern Region | E28: Haryana | F28: Central Sector | G28: Total | H28: Natural Gas | I28: 431.59 | J28: 150 | K28: 12 | L28: 0.01 | M28: 0 | N28: 0.08 | O28: 0 | P28: 51 | Q28: 70.2 | R28: 2.55 | S28: 137.65 | T28: 2752.94 | U28: NA | V28: NA | W28: NA | X28: NA | Y28: NA | Z28: NA
A29: July 2023 | B29: power_generation_2023_07_july.csv | C29: 28 | D29: Northern Region | E29: Haryana | F29: Central Sector | G29: Total | H29: Haryana | I29: 5761.59 | J29: 29650 | K29: 2407 | L29: 2385.26 | M29: 2960.94 | N29: 99.1 | O29: 80.56 | P29: 11259 | Q29: 9324.64 | R29: 11771.43 | S29: 82.82 | T29: 79.21 | U29: NA | V29: NA | W29: NA | X29: NA | Y29: NA | Z29: NA
A30: July 2023 | B30: power_generation_2023_07_july.csv | C30: 29 | D30: Northern Region | E30: Himachal Pradesh | F30: State Sector | G30: KASHANG INTEGRATED HEP | H30: NA | I30: 195 | J30: 185 | K30: 38 | L30: 22.28 | M30: 33.84 | N30: 58.63 | O30: 65.84 | P30: 97 | Q30: 79.17 | R30: 91.36 | S30: 81.62 | T30: 86.66 | U30: NA | V30: NA | W30: NA | X30: NA | Y30: NA | Z30: NA
A31: July 2023 | B31: power_generation_2023_07_july.csv | C31: 30 | D31: Northern Region | E31: Himachal Pradesh | F31: State Sector | G31: SAINJ HPS | H31: NA | I31: 100 | J31: 389 | K31: 75 | L31: 30.92 | M31: 79.13 | N31: 41.23 | O31: 39.07 | P31: 168 | Q31: 149.31 | R31: 176.2 | S31: 88.88 | T31: 84.74 | U31: NA | V31: NA | W31: NA | X31: NA | Y31: NA | Z31: NA
A32: July 2023 | B32: power_generation_2023_07_july.csv | C32: 31 | D32: Northern Region | E32: Himachal Pradesh | F32: State Sector | G32: SAWRA KUDDU HPS | H32: NA | I32: 111 | J32: 300 | K32: 44 | L32: 40.64 | M32: 52.74 | N32: 92.36 | O32: 77.06 | P32: 108 | Q32: 144.24 | R32: 110.92 | S32: 133.56 | T32: 130.04 | U32: NA | V32: NA | W32: NA | X32: NA | Y32: NA | Z32: NA
A33: July 2023 | B33: power_generation_2023_07_july.csv | C33: 32 | D33: Northern Region | E33: Himachal Pradesh | F33: State Sector | G33: HPPCL | H33: Hydro | I33: 406 | J33: 874 | K33: 157 | L33: 93.84 | M33: 165.71 | N33: 59.77 | O33: 56.63 | P33: 373 | Q33: 372.72 | R33: 378.48 | S33: 99.92 | T33: 98.48 | U33: NA | V33: NA | W33: NA | X33: NA | Y33: NA | Z33: NA
A34: July 2023 | B34: power_generation_2023_07_july.csv | C34: 33 | D34: Northern Region | E34: Himachal Pradesh | F34: State Sector | G34: BASSI HPS | H34: NA | I34: 66 | J34: 304 | K34: 46 | L34: 44.86 | M34: 47.54 | N34: 97.52 | O34: 94.36 | P34: 153 | Q34: 152.8 | R34: 150.1 | S34: 99.87 | T34: 101.8 | U34: NA | V34: NA | W34: NA | X34: NA | Y34: NA | Z34: NA
A35: July 2023 | B35: power_generation_2023_07_july.csv | C35: 34 | D35: Northern Region | E35: Himachal Pradesh | F35: State Sector | G35: GIRI BATA HPS | H35: NA | I35: 60 | J35: 180 | K35: 23 | L35: 31.88 | M35: 30.84 | N35: 138.61 | O35: 103.37 | P35: 48 | Q35: 76.88 | R35: 48.12 | S35: 160.17 | T35: 159.77 | U35: NA | V35: NA | W35: NA | X35: NA | Y35: NA | Z35: NA
A36: July 2023 | B36: power_generation_2023_07_july.csv | C36: 35 | D36: Northern Region | E36: Himachal Pradesh | F36: State Sector | G36: LARJI HPS | H36: NA | I36: 126 | J36: 619 | K36: 99 | L36: 25.73 | M36: 89.22 | N36: 25.99 | O36: 28.84 | P36: 291 | Q36: 213.47 | R36: 261.96 | S36: 73.36 | T36: 81.49 | U36: NA | V36: NA | W36: NA | X36: NA | Y36: NA | Z36: NA
A37: July 2023 | B37: power_generation_2023_07_july.csv | C37: 36 | D37: Northern Region | E37: Himachal Pradesh | F37: State Sector | G37: SANJAY HPS | H37: NA | I37: 120 | J37: 550 | K37: 72 | L37: 67.71 | M37: 90.93 | N37: 94.04 | O37: 74.46 | P37: 235 | Q37: 240.6 | R37: 307.55 | S37: 102.38 | T37: 78.23 | U37: NA | V37: NA | W37: NA | X37: NA | Y37: NA | Z37: NA
A38: July 2023 | B38: power_generation_2023_07_july.csv | C38: 37 | D38: Northern Region | E38: Himachal Pradesh | F38: State Sector | G38: UHL-III HPS | H38: NA | I38: 0 | J38: 0 | K38: 0 | L38: 0 | M38: 0 | N38: 0 | O38: 0 | P38: 0 | Q38: 0 | R38: 0 | S38: 0 | T38: 0 | U38: NA | V38: NA | W38: NA | X38: NA | Y38: NA | Z38: NA
A39: July 2023 | B39: power_generation_2023_07_july.csv | C39: 38 | D39: Northern Region | E39: Himachal Pradesh | F39: State Sector | G39: HPSEB | H39: Hydro | I39: 372 | J39: 1653 | K39: 240 | L39: 170.18 | M39: 258.53 | N39: 70.91 | O39: 65.83 | P39: 727 | Q39: 683.75 | R39: 767.73 | S39: 94.05 | T39: 89.06 | U39: NA | V39: NA | W39: NA | X39: NA | Y39: NA | Z39: NA
... A110: July 2023 | B110: power_generation_2023_07_july.csv | C110: 109 | D110: Northern Region | E110: Ladakh | F110: Central Sector | G110: Total | H110: Ladakh | I110: 89 | J110: 430 | K110: 63 | L110: 65.71 | M110: 64.79 | N110: 104.3 | O110: 101.42 | P110: 185 | Q110: 150.8 | R110: 173.43 | S110: 81.51 | T110: 86.95 | U110: NA | V110: NA | W110: NA | X110: NA | Y110: NA | Z110: NA
...

Sheet Clean Data
A1: Record_ID | B1: Period | C1: Month | D1: Days_In_Month | E1: Region | F1: State | G1: Sector | H1: Station_Name | I1: Fuel_Type | J1: Capacity_MW | K1: Target_MU | L1: Actual_MU | M1: Last_Year_MU | N1: Variance_MU | O1: Target_Met_Pct | P1: YoY_Growth_Pct | Q1: Plant_Efficiency_Pct
A2: 2023-07_1 | B2: 2023-07 | C2: July | D2: 31 | E2: Northern Region | F2: Delhi | G2: State Sector | H2: I.P.CCPP | I2: Natural Gas | J2: 270 | K2: 12 | L2: 27.58 | M2: 27.58 | N2: =L2-K2 -> 15.58 | O2: =IFERROR(L2/K2, 0) -> 2.2983333 | P2: =IFERROR((L2-M2)/M2, 0) -> 0 | Q2: =IFERROR((L2*1000)/(J2*D2*24), 0) -> 0.1372959
A3: 2023-07_3 | B3: 2023-07 | C3: July | D3: 31 | E3: Northern Region | F3: Delhi | G3: State Sector | H3: PRAGATI CCGT-III | I3: Natural Gas | J3: 1500 | K3: 342 | L3: 91.46 | M3: 214.86 | N3: =L3-K3 -> -250.54 | O3: =IFERROR(L3/K3, 0) -> 0.2674269 | P3: =IFERROR((L3-M3)/M3, 0) -> -0.57432747 | Q3: =IFERROR((L3*1000)/(J3*D3*24), 0) -> 0.081953405
A4: 2023-07_4 | B4: 2023-07 | C4: July | D4: 31 | E4: Northern Region | F4: Delhi | G4: State Sector | H4: PRAGATI CCPP | I4: Natural Gas | J4: 330.4 | K4: 119 | L4: 121.82 | M4: 132.37 | N4: =L4-K4 -> 2.82 | O4: =IFERROR(L4/K4, 0) -> 1.0236975 | P4: =IFERROR((L4-M4)/M4, 0) -> -0.079700839 | Q4: =IFERROR((L4*1000)/(J4*D4*24), 0) -> 0.4955707
A5: 2023-07_7 | B5: 2023-07 | C5: July | D5: 31 | E5: Northern Region | F5: Delhi | G5: Private Sector | H5: RITHALA CCPP | I5: Natural Gas | J5: 108 | K5: 0 | L5: 0 | M5: 0 | N5: =L5-K5 -> 0 | O5: =IFERROR(L5/K5, 0) -> 0 | P5: =IFERROR((L5-M5)/M5, 0) -> 0 | Q5: =IFERROR((L5*1000)/(J5*D5*24), 0) -> 0
A6: 2023-07_12 | B6: 2023-07 | C6: July | D6: 31 | E6: Northern Region | F6: Haryana | G6: State Sector | H6: PANIPAT TPS | I6: Coal / Thermal | J6: 710 | K6: 305 | L6: 430.22 | M6: 458.14 | N6: =L6-K6 -> 125.22 | O6: =IFERROR(L6/K6, 0) -> 1.4105574 | P6: =IFERROR((L6-M6)/M6, 0) -> -0.06094207 | Q6: =IFERROR((L6*1000)/(J6*D6*24), 0) -> 0.81444041
A7: 2023-07_13 | B7: 2023-07 | C7: July | D7: 31 | E7: Northern Region | F7: Haryana | G7: State Sector | H7: RAJIV GANDHI TPS | I7: Coal / Thermal | J7: 1200 | K7: 553 | L7: 267.13 | M7: 620.32 | N7: =L7-K7 -> -285.87 | O7: =IFERROR(L7/K7, 0) -> 0.48305606 | P7: =IFERROR((L7-M7)/M7, 0) -> -0.56936742 | Q7: =IFERROR((L7*1000)/(J7*D7*24), 0) -> 0.29920475
A8: 2023-07_14 | B8: 2023-07 | C8: July | D8: 31 | E8: Northern Region | F8: Haryana | G8: State Sector | H8: YAMUNA NAGAR TPS | I8: Coal / Thermal | J8: 600 | K8: 320 | L8: 293.92 | M8: 370.68 | N8: =L8-K8 -> -26.08 | O8: =IFERROR(L8/K8, 0) -> 0.9185 | P8: =IFERROR((L8-M8)/M8, 0) -> -0.20707888 | Q8: =IFERROR((L8*1000)/(J8*D8*24), 0) -> 0.65842294
A9: 2023-07_17 | B9: 2023-07 | C9: July | D9: 31 | E9: Northern Region | F9: Haryana | G9: Private Sector | H9: MAHATMA GANDHI TPS | I9: Coal / Thermal | J9: 1320 | K9: 614 | L9: 718.48 | M9: 801.6 | N9: =L9-K9 -> 104.48 | O9: =IFERROR(L9/K9, 0) -> 1.1701629 | P9: =IFERROR((L9-M9)/M9, 0) -> -0.10369261 | Q9: =IFERROR((L9*1000)/(J9*D9*24), 0) -> 0.73159009
A10: 2023-07_20 | B10: 2023-07 | C10: July | D10: 31 | E10: Northern Region | F10: Haryana | G10: Central Sector | H10: INDIRA GANDHI STPP | I10: Coal / Thermal | J10: 1500 | K10: 603 | L10: 675.5 | M10: 710.2 | N10: =L10-K10 -> 72.5 | O10: =IFERROR(L10/K10, 0) -> 1.1202322 | P10: =IFERROR((L10-M10)/M10, 0) -> -0.048859476 | Q10: =IFERROR((L10*1000)/(J10*D10*24), 0) -> 0.60528674
A11: 2023-07_23 | B11: 2023-07 | C11: July | D11: 31 | E11: Northern Region | F11: Haryana | G11: Central Sector | H11: FARIDABAD CCPP | I11: Natural Gas | J11: 431.59 | K11: 12 | L11: 0.01 | M11: 0 | N11: =L11-K11 -> -11.99 | O11: =IFERROR(L11/K11, 0) -> 0.00083333333 | P11: =IFERROR((L11-M11)/M11, 0) -> 0 | Q11: =IFERROR((L11*1000)/(J11*D11*24), 0) -> 3.1142659e-05
A12: 2023-07_29 | B12: 2023-07 | C12: July | D12: 31 | E12: Northern Region | F12: Himachal Pradesh | G12: State Sector | H12: KASHANG INTEGRATED HEP | I12: Hydro | J12: 195 | K12: 38 | L12: 22.28 | M12: 33.84 | N12: =L12-K12 -> -15.72 | O12: =IFERROR(L12/K12, 0) -> 0.58631579 | P12: =IFERROR((L12-M12)/M12, 0) -> -0.34160757 | Q12: =IFERROR((L12*1000)/(J12*D12*24), 0) -> 0.15357044
A13: 2023-07_30 | B13: 2023-07 | C13: July | D13: 31 | E13: Northern Region | F13: Himachal Pradesh | G13: State Sector | H13: SAINJ HPS | I13: Hydro | J13: 100 | K13: 75 | L13: 30.92 | M13: 79.13 | N13: =L13-K13 -> -44.08 | O13: =IFERROR(L13/K13, 0) -> 0.41226667 | P13: =IFERROR((L13-M13)/M13, 0) -> -0.6092506 | Q13: =IFERROR((L13*1000)/(J13*D13*24), 0) -> 0.4155914
... A3641: 2024-01_1034 | B3641: 2024-01 | C3641: January | D3641: 31 | E3641: North Eastern Region | F3641: Tripura | G3641: Central Sector | H3641: TRIPURA CCPP | I3641: Natural Gas | J3641: 726.6 | K3641: 426 | L3641: 356.26 | M3641: 442.44 | N3641: =L3641-K3641 -> -69.74 | O3641: =IFERROR(L3641/K3641, 0) -> 0.83629108 | P3641: =IFERROR((L3641-M3641)/M3641, 0) -> -0.19478347 | Q3641: =IFERROR((L3641*1000)/(J3641*D3641*24), 0) -> 0.65902021

Sheet Pivot Analysis
A1: POWER GENERATION SUMMARY PIVOT TABLES
A5: 1. Monthly Generation (Target vs Actual) | E5: 2. Fuel Source Breakdown | I5: 3. Regional Grid Performance
A6: Month | B6: Target (MU) | C6: Actual Power (MU) | E6: Fuel_Type | F6: Actual Power (MU) | G6: Target (MU) | I6: Region | J6: Actual Power (MU) | K6: Target (MU)
A7: January | B7: 122595 | C7: 128009.19 | E7: Coal / Thermal | F7: 748751.53 | G7: 714098 | I7: Eastern Region | J7: 154429.5 | K7: 154080
A8: July | B8: 123954 | C8: 125054.42 | E8: Hydro | F8: 86352.33 | G8: 100034 | I8: North Eastern Region | J8: 11691.09 | K8: 15743
A9: August | B9: 130942 | C9: 137077.66 | E9: Natural Gas | F9: 18149.45 | G9: 17899 | I9: North Eastern Region Region | J9: 1602.62 | K9: 2127
A10: September | B10: 126633 | C10: 129669.07 | E10: Nuclear | F10: 30197.58 | G10: 27453 | I10: Northern Region | J10: 218245.86 | K10: 220063
A11: October | B11: 118985 | C11: 132992.63 | E11: Grand Total | F11: 883450.89 | G11: 859484 | I11: Southern Region | J11: 165906.33 | K11: 170867
A12: November | B12: 117524 | C12: 114712.75 | I12: Western Region | J12: 331575.49 | K12: 296604
A13: December | B13: 118851 | C13: 115935.17 | I13: Grand Total | J13: 883450.89 | K13: 859484
A14: Grand Total | B14: 859484 | C14: 883450.89

Sheet Dashboard
A1: INDIA POWER GENERATION DASHBOARD
A5: TOTAL ACTUAL GENERATION | D5: PLANNED TARGET | G5: TARGET FULFILLMENT RATE | J5: CLEAN & GAS SHARE
A6: =SUM('Clean Data'!$L$2:$L$3641) -> 883450.89 | D6: =SUM('Clean Data'!$K$2:$K$3641) -> 859484 | G6: =IFERROR(A6/D6, 0) -> 1.0278852 | J6: =(SUMIF('Clean Data'!$I$2:$I$3641, "Hydro", 'Clean Data'!$L$2:$L$3641) + SUMIF('Clean Data'!$I$2:$I$3641, "Nuclear", 'Clean Data'!$L$2:$L$3641) + SUMIF('Clean Data'!$I$2:$I$3641, "Natural Gas", 'Clean Data'!$L$2:$L$3641)) / A6 -> 0.15246955
A9: Month | B9: Target (MU) | C9: Actual (MU) | E9: Fuel Source | F9: Actual Power (MU)
A10: July | B10: =SUMIF('Clean Data'!$B$2:$B$3641, "2023-07", 'Clean Data'!$K$2:$K$3641) -> 123954 | C10: =SUMIF('Clean Data'!$B$2:$B$3641, "2023-07", 'Clean Data'!$L$2:$L$3641) -> 125054.42 | E10: Coal / Thermal | F10: =SUMIF('Clean Data'!$I$2:$I$3641, "Coal / Thermal", 'Clean Data'!$L$2:$L$3641) -> 748751.53
A11: August | B11: =SUMIF('Clean Data'!$B$2:$B$3641, "2023-08", 'Clean Data'!$K$2:$K$3641) -> 130942 | C11: =SUMIF('Clean Data'!$B$2:$B$3641, "2023-08", 'Clean Data'!$L$2:$L$3641) -> 137077.66 | E11: Hydro | F11: =SUMIF('Clean Data'!$I$2:$I$3641, "Hydro", 'Clean Data'!$L$2:$L$3641) -> 86352.33
A12: September | B12: =SUMIF('Clean Data'!$B$2:$B$3641, "2023-09", 'Clean Data'!$K$2:$K$3641) -> 126633 | C12: =SUMIF('Clean Data'!$B$2:$B$3641, "2023-09", 'Clean Data'!$L$2:$L$3641) -> 129669.07 | E12: Nuclear | F12: =SUMIF('Clean Data'!$I$2:$I$3641, "Nuclear", 'Clean Data'!$L$2:$L$3641) -> 30197.58
A13: October | B13: =SUMIF('Clean Data'!$B$2:$B$3641, "2023-10", 'Clean Data'!$K$2:$K$3641) -> 118985 | C13: =SUMIF('Clean Data'!$B$2:$B$3641, "2023-10", 'Clean Data'!$L$2:$L$3641) -> 132992.63 | E13: Natural Gas | F13: =SUMIF('Clean Data'!$I$2:$I$3641, "Natural Gas", 'Clean Data'!$L$2:$L$3641) -> 18149.45
A14: November | B14: =SUMIF('Clean Data'!$B$2:$B$3641, "2023-11", 'Clean Data'!$K$2:$K$3641) -> 117524 | C14: =SUMIF('Clean Data'!$B$2:$B$3641, "2023-11", 'Clean Data'!$L$2:$L$3641) -> 114712.75
A15: December | B15: =SUMIF('Clean Data'!$B$2:$B$3641, "2023-12", 'Clean Data'!$K$2:$K$3641) -> 118851 | C15: =SUMIF('Clean Data'!$B$2:$B$3641, "2023-12", 'Clean Data'!$L$2:$L$3641) -> 115935.17
A16: January | B16: =SUMIF('Clean Data'!$B$2:$B$3641, "2024-01", 'Clean Data'!$K$2:$K$3641) -> 122595 | C16: =SUMIF('Clean Data'!$B$2:$B$3641, "2024-01", 'Clean Data'!$L$2:$L$3641) -> 128009.19
A37: Grid Region | B37: Target (MU) | C37: Actual Power (MU) | D37: Target Met % | E37: National Share %
A38: Western Region | B38: =SUMIF('Clean Data'!$E$2:$E$3641, A38, 'Clean Data'!$K$2:$K$3641) -> 296604 | C38: =SUMIF('Clean Data'!$E$2:$E$3641, A38, 'Clean Data'!$L$2:$L$3641) -> 331575.49 | D38: =IFERROR(C38/B38, 0) -> 1.1179063 | E38: =IFERROR(C38/$C$43, 0) -> 0.37600061
A39: Northern Region | B39: =SUMIF('Clean Data'!$E$2:$E$3641, A39, 'Clean Data'!$K$2:$K$3641) -> 220063 | C39: =SUMIF('Clean Data'!$E$2:$E$3641, A39, 'Clean Data'!$L$2:$L$3641) -> 218245.86 | D39: =IFERROR(C39/B39, 0) -> 0.99174264 | E39: =IFERROR(C39/$C$43, 0) -> 0.24748686
A40: Southern Region | B40: =SUMIF('Clean Data'!$E$2:$E$3641, A40, 'Clean Data'!$K$2:$K$3641) -> 170867 | C40: =SUMIF('Clean Data'!$E$2:$E$3641, A40, 'Clean Data'!$L$2:$L$3641) -> 165906.33 | D40: =IFERROR(C40/B40, 0) -> 0.97096765 | E40: =IFERROR(C40/$C$43, 0) -> 0.18813478
A41: Eastern Region | B41: =SUMIF('Clean Data'!$E$2:$E$3641, A41, 'Clean Data'!$K$2:$K$3641) -> 154080 | C41: =SUMIF('Clean Data'!$E$2:$E$3641, A41, 'Clean Data'!$L$2:$L$3641) -> 154429.5 | D41: =IFERROR(C41/B41, 0) -> 1.0022683 | E41: =IFERROR(C41/$C$43, 0) -> 0.17512026
A42: North Eastern Region | B42: =SUMIF('Clean Data'!$E$2:$E$3641, A42, 'Clean Data'!$K$2:$K$3641) -> 15743 | C42: =SUMIF('Clean Data'!$E$2:$E$3641, A42, 'Clean Data'!$L$2:$L$3641) -> 11691.09 | D42: =IFERROR(C42/B42, 0) -> 0.74262148 | E42: =IFERROR(C42/$C$43, 0) -> 0.013257485
A43: NATIONAL TOTAL | B43: =SUM(B38:B42) -> 857357 | C43: =SUM(C38:C42) -> 881848.27 | D43: =IFERROR(C43/B43, 0) -> 1.028566 | E43: =SUM(E38:E42) -> 1
